Traceback (most recent call last):
  File "/Users/bekzodamonov/anaconda3/lib/python3.11/site-packages/jupyter_cache/executors/utils.py", line 58, in single_nb_execution
    executenb(
  File "/Users/bekzodamonov/anaconda3/lib/python3.11/site-packages/nbclient/client.py", line 1204, in execute
    return NotebookClient(nb=nb, resources=resources, km=km, **kwargs).execute()
           ^^^^^^^^^^^^^^^^^^^^^^^^^^^^^^^^^^^^^^^^^^^^^^^^^^^^^^^^^^^^^^^^^^^^^
  File "/Users/bekzodamonov/anaconda3/lib/python3.11/site-packages/nbclient/util.py", line 84, in wrapped
    return just_run(coro(*args, **kwargs))
           ^^^^^^^^^^^^^^^^^^^^^^^^^^^^^^^
  File "/Users/bekzodamonov/anaconda3/lib/python3.11/site-packages/nbclient/util.py", line 62, in just_run
    return loop.run_until_complete(coro)
           ^^^^^^^^^^^^^^^^^^^^^^^^^^^^^
  File "/Users/bekzodamonov/anaconda3/lib/python3.11/asyncio/base_events.py", line 653, in run_until_complete
    return future.result()
           ^^^^^^^^^^^^^^^
  File "/Users/bekzodamonov/anaconda3/lib/python3.11/site-packages/nbclient/client.py", line 663, in async_execute
    await self.async_execute_cell(
  File "/Users/bekzodamonov/anaconda3/lib/python3.11/site-packages/nbclient/client.py", line 965, in async_execute_cell
    await self._check_raise_for_error(cell, cell_index, exec_reply)
  File "/Users/bekzodamonov/anaconda3/lib/python3.11/site-packages/nbclient/client.py", line 862, in _check_raise_for_error
    raise CellExecutionError.from_cell_and_msg(cell, exec_reply_content)
nbclient.exceptions.CellExecutionError: An error occurred while executing the following cell:
------------------
#Scaling the test data features
X_test_interactions = test_df[refined_features]
X_test_scaled_interactions = scaler.transform(X_test_interactions)

# Generating predictions using the stacking model with interaction terms
final_test_predictions = stacking_model_refined.predict(X_test_scaled_interactions)

# Creating the submission DataFrame
final_submission = pd.DataFrame({
    'PassengerId': test_df['PassengerId'],
    'Survived': final_test_predictions
})

# Saving the submission file
submission_file_path = 'titanic_stacking_submission-final.csv'
final_submission.to_csv(submission_file_path, index=False)

submission_file_path
------------------

[0;31m---------------------------------------------------------------------------[0m
[0;31mKeyError[0m                                  Traceback (most recent call last)
Cell [0;32mIn[17], line 2[0m
[1;32m      1[0m [38;5;66;03m#Scaling the test data features[39;00m
[0;32m----> 2[0m X_test_interactions [38;5;241m=[39m test_df[refined_features]
[1;32m      3[0m X_test_scaled_interactions [38;5;241m=[39m scaler[38;5;241m.[39mtransform(X_test_interactions)
[1;32m      5[0m [38;5;66;03m# Generating predictions using the stacking model with interaction terms[39;00m

File [0;32m~/anaconda3/lib/python3.11/site-packages/pandas/core/frame.py:3767[0m, in [0;36mDataFrame.__getitem__[0;34m(self, key)[0m
[1;32m   3765[0m     [38;5;28;01mif[39;00m is_iterator(key):
[1;32m   3766[0m         key [38;5;241m=[39m [38;5;28mlist[39m(key)
[0;32m-> 3767[0m     indexer [38;5;241m=[39m [38;5;28mself[39m[38;5;241m.[39mcolumns[38;5;241m.[39m_get_indexer_strict(key, [38;5;124m"[39m[38;5;124mcolumns[39m[38;5;124m"[39m)[[38;5;241m1[39m]
[1;32m   3769[0m [38;5;66;03m# take() does not accept boolean indexers[39;00m
[1;32m   3770[0m [38;5;28;01mif[39;00m [38;5;28mgetattr[39m(indexer, [38;5;124m"[39m[38;5;124mdtype[39m[38;5;124m"[39m, [38;5;28;01mNone[39;00m) [38;5;241m==[39m [38;5;28mbool[39m:

File [0;32m~/anaconda3/lib/python3.11/site-packages/pandas/core/indexes/base.py:5877[0m, in [0;36mIndex._get_indexer_strict[0;34m(self, key, axis_name)[0m
[1;32m   5874[0m [38;5;28;01melse[39;00m:
[1;32m   5875[0m     keyarr, indexer, new_indexer [38;5;241m=[39m [38;5;28mself[39m[38;5;241m.[39m_reindex_non_unique(keyarr)
[0;32m-> 5877[0m [38;5;28mself[39m[38;5;241m.[39m_raise_if_missing(keyarr, indexer, axis_name)
[1;32m   5879[0m keyarr [38;5;241m=[39m [38;5;28mself[39m[38;5;241m.[39mtake(indexer)
[1;32m   5880[0m [38;5;28;01mif[39;00m [38;5;28misinstance[39m(key, Index):
[1;32m   5881[0m     [38;5;66;03m# GH 42790 - Preserve name from an Index[39;00m

File [0;32m~/anaconda3/lib/python3.11/site-packages/pandas/core/indexes/base.py:5941[0m, in [0;36mIndex._raise_if_missing[0;34m(self, key, indexer, axis_name)[0m
[1;32m   5938[0m     [38;5;28;01mraise[39;00m [38;5;167;01mKeyError[39;00m([38;5;124mf[39m[38;5;124m"[39m[38;5;124mNone of [[39m[38;5;132;01m{[39;00mkey[38;5;132;01m}[39;00m[38;5;124m] are in the [[39m[38;5;132;01m{[39;00maxis_name[38;5;132;01m}[39;00m[38;5;124m][39m[38;5;124m"[39m)
[1;32m   5940[0m not_found [38;5;241m=[39m [38;5;28mlist[39m(ensure_index(key)[missing_mask[38;5;241m.[39mnonzero()[[38;5;241m0[39m]][38;5;241m.[39munique())
[0;32m-> 5941[0m [38;5;28;01mraise[39;00m [38;5;167;01mKeyError[39;00m([38;5;124mf[39m[38;5;124m"[39m[38;5;132;01m{[39;00mnot_found[38;5;132;01m}[39;00m[38;5;124m not in index[39m[38;5;124m"[39m)

[0;31mKeyError[0m: "['FamilySize'] not in index"
KeyError: "['FamilySize'] not in index"

