Traceback (most recent call last):
  File "/Users/bekzodamonov/Library/CloudStorage/GoogleDrive-bekzod.amonov.study@gmail.com/My Drive/TU DORTMUND/Introduction with Python/final-project-submit/venv/lib/python3.11/site-packages/jupyter_cache/executors/utils.py", line 58, in single_nb_execution
    executenb(
  File "/Users/bekzodamonov/Library/CloudStorage/GoogleDrive-bekzod.amonov.study@gmail.com/My Drive/TU DORTMUND/Introduction with Python/final-project-submit/venv/lib/python3.11/site-packages/nbclient/client.py", line 1314, in execute
    return NotebookClient(nb=nb, resources=resources, km=km, **kwargs).execute()
           ^^^^^^^^^^^^^^^^^^^^^^^^^^^^^^^^^^^^^^^^^^^^^^^^^^^^^^^^^^^^^^^^^^^^^
  File "/Users/bekzodamonov/Library/CloudStorage/GoogleDrive-bekzod.amonov.study@gmail.com/My Drive/TU DORTMUND/Introduction with Python/final-project-submit/venv/lib/python3.11/site-packages/jupyter_core/utils/__init__.py", line 165, in wrapped
    return loop.run_until_complete(inner)
           ^^^^^^^^^^^^^^^^^^^^^^^^^^^^^^
  File "/Users/bekzodamonov/anaconda3/lib/python3.11/asyncio/base_events.py", line 653, in run_until_complete
    return future.result()
           ^^^^^^^^^^^^^^^
  File "/Users/bekzodamonov/Library/CloudStorage/GoogleDrive-bekzod.amonov.study@gmail.com/My Drive/TU DORTMUND/Introduction with Python/final-project-submit/venv/lib/python3.11/site-packages/nbclient/client.py", line 709, in async_execute
    await self.async_execute_cell(
  File "/Users/bekzodamonov/Library/CloudStorage/GoogleDrive-bekzod.amonov.study@gmail.com/My Drive/TU DORTMUND/Introduction with Python/final-project-submit/venv/lib/python3.11/site-packages/nbclient/client.py", line 1062, in async_execute_cell
    await self._check_raise_for_error(cell, cell_index, exec_reply)
  File "/Users/bekzodamonov/Library/CloudStorage/GoogleDrive-bekzod.amonov.study@gmail.com/My Drive/TU DORTMUND/Introduction with Python/final-project-submit/venv/lib/python3.11/site-packages/nbclient/client.py", line 918, in _check_raise_for_error
    raise CellExecutionError.from_cell_and_msg(cell, exec_reply_content)
nbclient.exceptions.CellExecutionError: An error occurred while executing the following cell:
------------------
import pandas as pd

# Load the provided datasets
train_file_path = 'train.csv'
test_file_path = 'test.csv'
gender_submission_file_path = 'gender_submission.csv'

# Reading the datasets
train_df = pd.read_csv(train_file_path)
test_df = pd.read_csv(test_file_path)
gender_submission_df = pd.read_csv(gender_submission_file_path)

# Displaying the first few rows of each dataset to understand their structure
train_head = train_df.head()
test_head = test_df.head()
gender_submission_head = gender_submission_df.head()

(train_head, test_head, gender_submission_head)

------------------


[0;31m---------------------------------------------------------------------------[0m
[0;31mModuleNotFoundError[0m                       Traceback (most recent call last)
Cell [0;32mIn[1], line 1[0m
[0;32m----> 1[0m [38;5;28;01mimport[39;00m [38;5;21;01mpandas[39;00m [38;5;28;01mas[39;00m [38;5;21;01mpd[39;00m
[1;32m      3[0m [38;5;66;03m# Load the provided datasets[39;00m
[1;32m      4[0m train_file_path [38;5;241m=[39m [38;5;124m'[39m[38;5;124mtrain.csv[39m[38;5;124m'[39m

[0;31mModuleNotFoundError[0m: No module named 'pandas'

